Workbook

Sheet COVER PAGE
A1: Field_1 | B1: Field_2 | C1: Field_3 | D1: Field_4 | E1: Field_5 | F1: Field_6 | G1: Field_7 | H1: Field_8
D3: OmniBSIC Bank Ghana Limited
B7: BANK AND NOSTRO RECONCILIATION REPORT
B11: 20-Nov-25

Sheet BOG GHS
A1: Field_1 | B1: Field_2 | C1: Field_3 | D1: Field_4 | E1: Field_5 | F1: Field_6 | G1: Field_7 | H1: Field_8 | I1: Field_9 | J1: Field_10
B4: DEPT | D4: OPERATIONS | E4: BANK ACCOUNT NUMBER | F4: 0120730044000/0120730031000
B6: BRANCH | D6: HEAD OFFICE | E6: GENERAL LEDGER NAME | F6: BOG GHS
B8: REPORTING DATE | D8: 20-Nov-25 | E8: GENERAL LEDGER NUMBER | F8: 0010000090013
B10: REPORTING UNIT | D10: RECONCILIATION
C13: 20-Nov-2025 | D13: BALANCE PER BANK STATEMENT | E13: 2.7180713e+09 | I13: CR
B15: SN | C15: DATE | D15: DESCRIPTION | E15: AMOUNT | F15: GL Ref No. | G15: AGING(DAYS) | H15: RECON
D17: ADD: DEBIT IN OUR BOOKS BUT NOT CREDITED BY BOG
B18: 1 | C18: 17-Nov-2025 | D18: 355 DAY REPO - ACCES BANK( SECONDARY MARKET) MM CONTRACT LIQUIDATION | E18: 8777458.4 | F18: 000MTTB243320001 | G18: 3 | H18: INT DR
B19: 2 | C19: 17-Nov-2025 | D19: 355 DAY REPO - ACCES BANK( SECONDARY MARKET) MM CONTRACT LIQUIDATION | E19: 29999942 | F19: 000MTTB243320001 | G19: 3 | H19: INT DR
B20: 3 | C20: 17-Nov-2025 | D20: 353 DAY GOG BILL PURCHASE - BANK MM CONTRACT LIQUIDATION | E20: 8757105.4 | F20: 000MTTB243340001 | G20: 3 | H20: INT DR
B21: 4 | C21: 17-Nov-2025 | D21: 353 DAY GOG BILL PURCHASE - BANK MM CONTRACT LIQUIDATION | E21: 29999895 | F21: 000MTTB243340001 | G21: 3 | H21: INT DR
B22: 5 | C22: 17-Nov-2025 | D22: 350 DAY GOG BILL - BANK MM CONTRACT LIQUIDATION | E22: 14471096 | F22: 000MTTB243370001 | G22: 3 | H22: INT DR
B23: 6 | C23: 17-Nov-2025 | D23: 350 DAY GOG BILL - BANK MM CONTRACT LIQUIDATION | E23: 49999904 | F23: 000MTTB243370001 | G23: 3 | H23: INT DR
B24: 7 | C24: 17-Nov-2025 | D24: 336 SECONDARY MK - ACCESS MM CONTRACT LIQUIDATION | E24: 42226577 | F24: 000MTTB243510003 | G24: 3 | H24: INT DR
B25: 8 | C25: 17-Nov-2025 | D25: 336 SECONDARY MK - ACCESS MM CONTRACT LIQUIDATION | E25: 1.49985e+08 | F25: 000MTTB243510003 | G25: 3 | H25: INT DR
B26: 9 | C26: 19-Nov-2025 | D26: COMMISSION ON TREASURY BILL DD 17.11.2025 | E26: 151661.14 | F26: 000TBIL253230001 | G26: 1 | H26: INT DR
D28: TOTAL: | E28: =SUM($E$18:$E$27) -> 3.3436864e+08
D31: ADD: DEBIT ORIGINATED BY BOG BUT NOT CREDITED IN OUR BOOKS
B32: 1 | C32: 17-Nov-2025 | D32: SCCT TROPSAUC171125AS GTBIGHAC OMNIBSIC BANK GHANA /201/119943/1/1/0 | E32: 62474150 | F32: TROPSAUC171125AS | G32: 3 | H32: EXT DR
B33: 2 | C33: 18-Nov-2025 | D33: 52 20251118 CSDT 20251118S0035084 ABNGGHAC //OPERATIONCODE //DeliveryVersusPayment | E33: 679018.92 | F33: 20251118S0035084 | G33: 2 | H33: EXT DR
B34: 3 | C34: 18-Nov-2025 | D34: 80 20251118 NSI MCI1181125 | E34: 175565.37 | F34: MCI1181125 | G34: 2 | H34: EXT DR
B35: 4 | C35: 19-Nov-2025 | D35: 90 20251119 NSI MCI1191125 | E35: 80115.52 | F35: MCI1191125 | G35: 1 | H35: EXT DR
B36: 5 | C36: 20-Nov-2025 | D36: 7 20251120 CSDT 20251120S0000254 SSNTGHAC //OPERATIONCODE //ReverseRepoCollateral | E36: 7120821.9 | F36: 20251120S0000254 | G36: 0 | H36: EXT DR
B37: 6 | C37: 20-Nov-2025 | D37: 19 20251120 CSDT 20251120S0002183 HFCAGHAC //OPERATIONCODE //DeliveryVersusPayment | E37: 3639615.3 | F37: 20251120S0002183 | G37: 0 | H37: EXT DR
B38: 7 | C38: 20-Nov-2025 | D38: 20 20251120 CSDT 20251120S0002184 HFCAGHAC //OPERATIONCODE //DeliveryVersusPayment | E38: 1455846.5 | F38: 20251120S0002184 | G38: 0 | H38: EXT DR
B39: 8 | C39: 20-Nov-2025 | D39: 28 20251120 CSDT 20251120S0003292 ECOCGHAC //OPERATIONCODE //DeliveryVersusPayment | E39: 935901.32 | F39: 20251120S0003292 | G39: 0 | H39: EXT DR
B40: 9 | C40: 20-Nov-2025 | D40: 45 20251120 NSI 20251120T0016320 /// | E40: 7488523.9 | F40: 20251120T0016320 | G40: 0 | H40: EXT DR
B41: 10 | C41: 20-Nov-2025 | D41: 81 20251120 NSI 20251120T0022076 /// | E41: 1503001.7 | F41: 20251120T0022076 | G41: 0 | H41: EXT DR
B42: 11 | C42: 20-Nov-2025 | D42: 82 20251120 NSI GG07181125 | E42: 3814249.1 | F42: GG07181125 | G42: 0 | H42: EXT DR
B43: 12 | C43: 20-Nov-2025 | D43: 83 20251120 NSI GG08181125 | E43: 1401529.7 | F43: GG08181125 | G43: 0 | H43: EXT DR
... B46: 15 | C46: 20-Nov-2025 | D46: FIT TRSF01201125FAAM FAMCGHAC ISSN 76035 MATURITY SETTLEMENT FAMCCUS- | E46: 1127638 | F46: TRSF01201125FAAM | G46: 0 | H46: EXT DR
D48: TOTAL: | E48: =SUM($E$32:$E$47) -> 1.2538639e+08
D51: LESS: CREDIT ORIGINATED BY BOG BUT NOT DEBITED IN OUR BOOKS
B52: 1 | C52: 17-Nov-2025 | D52: 37 20251117 NSI 20251117T0009403 /ISIN/GHGGOG076035 | E52: 333538868 | F52: 20251117T0009403 | G52: 3 | H52: EXT CR
B53: 2 | C53: 20-Nov-2025 | D53: 63 20251120 NSI RGIP181125 | E53: 3988 | F53: RGIP181125 | G53: 0 | H53: EXT CR
B54: 3 | C54: 20-Nov-2025 | D54: 64 20251120 NSI RGIP201125 /6010194725 | E54: 194997 | F54: RGIP201125 | G54: 0 | H54: EXT CR
B55: 4 | C55: 20-Nov-2025 | D55: 86 20251120 NSI VISA201125 | E55: 33403.32 | F55: VISA201125 | G55: 0 | H55: EXT CR
D57: TOTAL: | E57: =SUM($E$52:$E$56) -> 3.3377126e+08
D60: LESS: CREDIT IN OUR BOOKS BUT NOT DEBITED BY BOG
...

Sheet BOG USD
A1: Field_1 | B1: Field_2 | C1: Field_3 | D1: Field_4 | E1: Field_5 | F1: Field_6 | G1: Field_7 | H1: Field_8 | I1: Field_9 | J1: Field_10
B4: DEPT | D4: OPERATIONS | E4: BANK ACCOUNT NUMBER | F4: 1027232397011
B6: BRANCH | D6: HEAD OFFICE | E6: GENERAL LEDGER NAME | F6: BOG USD
B8: REPORTING DATE | D8: 20-Nov-25 | E8: GENERAL LEDGER NUMBER | F8: 0020000090010
B10: REPORTING UNIT | D10: RECONCILIATION
C13: 20-Nov-2025 | D13: BALANCE PER BANK STATEMENT | E13: 44709005 | I13: CR
B15: SN | C15: DATE | D15: DESCRIPTION | E15: AMOUNT | F15: GL Ref No. | G15: AGING(DAYS) | H15: RECON
D17: ADD: DEBIT IN OUR BOOKS BUT NOT CREDITED BY BOG
B18: 1 | C18: 12-Nov-2025 | D18: 0000189253160001_FINCON JOURNAL ENTRY | E18: 4400 | G18: 8 | H18: INT DR
B19: 2 | C19: 19-Nov-2025 | D19: FX PURCHASE - USD/GHS @ 11.10 (UNIV OF GH.) | E19: 200000 | F19: 2532301465187000 | G19: 1 | H19: INT DR
B20: 3 | C20: 20-Nov-2025 | D20: FX SALE - USD/GHS @ 11.10 (USD 140,000.00 MASTERCARD) | E20: 140000 | F20: 2532401461518000 | G20: 0 | H20: INT DR
B21: 4 | C21: 20-Nov-2025 | D21: FX SALE - USD/GHS @ 11.10 (USD 20,000.00 MASTERCARD) | E21: 20000 | F21: 2532401461593000 | G21: 0 | H21: INT DR
B22: 5 | C22: 20-Nov-2025 | D22: FX SALE - USD/GHS @ 11.10 (USD 100,000.00 MASTERCARD) | E22: 100000 | F22: 2532401461658000 | G22: 0 | H22: INT DR
D24: TOTAL: | E24: =SUM($E$18:$E$23) -> 464400
D27: ADD: DEBIT ORIGINATED BY BOG BUT NOT CREDITED IN OUR BOOKS
D30: TOTAL: | E30: =SUM($E$28:$E$29) -> 0
D33: LESS: CREDIT ORIGINATED BY BOG BUT NOT DEBITED IN OUR BOOKS
B34: 1 | C34: 03-Nov-2025 | D34: FNB253070KGFFJHL FIRNGHAC /2021015043307 GHANA SPECIALTY FATS INDUSTRIES LTD /0020039684014 AMARIS TERMINAL LIMITED WAREHOUSE RENTAL | E34: 15000 | G34: 17 | H34: EXT CR
B35: 2 | C35: 19-Nov-2025 | D35: 1 20251119 SCCT GTBFTDC251130741 GTBIGHAC /1027232397011 BENJAMIN CARGO LOGISTICS | E35: 600 | F35: GTBFTDC251130741 | G35: 1 | H35: EXT CR
B36: 3 | C36: 20-Nov-2025 | D36: 2 20251120 SCCT GH06432425HLE85 BARCGHAC /0020233906018 PAA YOOKU YAWSON | E36: 6000 | F36: GH06432425HLE85 | G36: 0 | H36: EXT CR
D38: TOTAL: | E38: =SUM($E$34:$E$37) -> 21600
D41: LESS: CREDIT IN OUR BOOKS BUT NOT DEBITED BY BOG
B42: 1 | C42: 13-Oct-2025 | D42: OMNCHQ20250995 PYT OF CHQ#009463 IFO ETHOS RISK PROTECTION PARTNERS | E42: 67.02 | G42: 38 | H42: INT CR
B43: 2 | C43: 13-Nov-2025 | D43: OMNCHQ20251031 PYT OF CHQ#000106 IFO KHADIJA ADAM | E43: 345.73 | F43: OMNCHQ20251031 | G43: 7 | H43: INT CR
D45: TOTAL: | E45: =SUM($E$42:$E$44) -> 412.75
D48: GRAND TOTAL | E48: =ABS(E13+$E$24-$E$45+$E$30-$E$38) -> 45151392
D49: INTERNAL ACCOUNT BALANCE AS AT Nov 20, 2025 | E49: 45151392 | I49: DR
D50: DIFFERENCE | E50: =$E$49-$E$48 -> 0
D52: PREPARED BY: | E52: kenneth nuamah | F52: DATE: | G52: 45981
D55: REVIEWED BY: | F55: DATE:

Sheet BOG EUR
A1: Field_1 | B1: Field_2 | C1: Field_3 | D1: Field_4 | E1: Field_5 | F1: Field_6 | G1: Field_7 | H1: Field_8 | I1: Field_9 | J1: Field_10
B4: DEPT | D4: OPERATIONS | E4: BANK ACCOUNT NUMBER | F4: ^1187232397019
B6: BRANCH | D6: HEAD OFFICE | E6: GENERAL LEDGER NAME | F6: BOG EUR
B8: REPORTING DATE | D8: 20-Nov-25 | E8: GENERAL LEDGER NUMBER | F8: 0030000090018
B10: REPORTING UNIT | D10: RECONCILIATION
C13: 20-Nov-2025 | D13: BALANCE PER BANK STATEMENT | E13: 1063124.2 | I13: CR
B15: SN | C15: DATE | D15: DESCRIPTION | E15: AMOUNT | F15: GL Ref No. | G15: AGING(DAYS) | H15: RECON
D17: ADD: DEBIT IN OUR BOOKS BUT NOT CREDITED BY BOG
D20: TOTAL: | E20: =SUM($E$18:$E$19) -> 0
D23: ADD: DEBIT ORIGINATED BY BOG BUT NOT CREDITED IN OUR BOOKS
D26: TOTAL: | E26: =SUM($E$24:$E$25) -> 0
D29: LESS: CREDIT ORIGINATED BY BOG BUT NOT DEBITED IN OUR BOOKS
D32: TOTAL: | E32: =SUM($E$30:$E$31) -> 0
D35: LESS: CREDIT IN OUR BOOKS BUT NOT DEBITED BY BOG
D38: TOTAL: | E38: =SUM($E$36:$E$37) -> 0
D41: GRAND TOTAL | E41: =ABS(E13+$E$20-$E$38+$E$26-$E$32) -> 1063124.2
D42: INTERNAL ACCOUNT BALANCE AS AT Nov 20, 2025 | E42: 1063124.2 | I42: DR
D43: DIFFERENCE | E43: =$E$42-$E$41 -> 0
D45: PREPARED BY: | E45: kenneth nuamah | F45: DATE: | G45: 45981
D48: REVIEWED BY: | F48: DATE:

Sheet BOG GBP
A1: Field_1 | B1: Field_2 | C1: Field_3 | D1: Field_4 | E1: Field_5 | F1: Field_6 | G1: Field_7 | H1: Field_8 | I1: Field_9 | J1: Field_10
B4: DEPT | D4: OPERATIONS | E4: BANK ACCOUNT NUMBER | F4: ^1037232397017
B6: BRANCH | D6: HEAD OFFICE | E6: GENERAL LEDGER NAME | F6: BOG GBP
B8: REPORTING DATE | D8: 20-Nov-25 | E8: GENERAL LEDGER NUMBER | F8: 0040000090015
B10: REPORTING UNIT | D10: RECONCILIATION
C13: 20-Nov-2025 | D13: BALANCE PER BANK STATEMENT | E13: 703521.11 | I13: CR
B15: SN | C15: DATE | D15: DESCRIPTION | E15: AMOUNT | F15: GL Ref No. | G15: AGING(DAYS) | H15: RECON
D17: ADD: DEBIT IN OUR BOOKS BUT NOT CREDITED BY BOG
D20: TOTAL: | E20: =SUM($E$18:$E$19) -> 0
D23: ADD: DEBIT ORIGINATED BY BOG BUT NOT CREDITED IN OUR BOOKS
D26: TOTAL: | E26: =SUM($E$24:$E$25) -> 0
D29: LESS: CREDIT ORIGINATED BY BOG BUT NOT DEBITED IN OUR BOOKS
D32: TOTAL: | E32: =SUM($E$30:$E$31) -> 0
D35: LESS: CREDIT IN OUR BOOKS BUT NOT DEBITED BY BOG
D38: TOTAL: | E38: =SUM($E$36:$E$37) -> 0
D41: GRAND TOTAL | E41: =ABS(E13+$E$20-$E$38+$E$26-$E$32) -> 703521.11
D42: INTERNAL ACCOUNT BALANCE AS AT Nov 20, 2025 | E42: 703521.11 | I42: DR
D43: DIFFERENCE | E43: =$E$42-$E$41 -> 0
D45: PREPARED BY: | E45: kenneth nuamah | F45: DATE: | G45: 45981
D48: REVIEWED BY: | F48: DATE:

Sheet BOG PAPSS GHS
A1: Field_1 | B1: Field_2 | C1: Field_3 | D1: Field_4 | E1: Field_5 | F1: Field_6 | G1: Field_7 | H1: Field_8 | I1: Field_9 | J1: Field_10
B4: DEPT | D4: OPERATIONS | E4: BANK ACCOUNT NUMBER | F4: GH100017
B6: BRANCH | D6: HEAD OFFICE | E6: GENERAL LEDGER NAME | F6: BOG -ACCRA- PAPSS
B8: REPORTING DATE | D8: 20-Nov-25 | E8: GENERAL LEDGER NUMBER | F8: 0010000090024
B10: REPORTING UNIT | D10: RECONCILIATION
C13: 20-Nov-2025 | D13: BALANCE PER BANK STATEMENT | E13: 103818.35 | I13: CR
B15: SN | C15: DATE | D15: DESCRIPTION | E15: AMOUNT | F15: GL Ref No. | G15: AGING(DAYS) | H15: RECON
D17: ADD: DEBIT IN OUR BOOKS BUT NOT CREDITED BY BOG
B18: 1 | C18: 07-Nov-2025 | D18: Allowance to mother | E18: 719.14 | F18: 7679014267440990 | G18: 13 | H18: INT DR
D20: TOTAL: | E20: =SUM($E$18:$E$19) -> 719.14
D23: ADD: DEBIT ORIGINATED BY BOG BUT NOT CREDITED IN OUR BOOKS
D26: TOTAL: | E26: =SUM($E$24:$E$25) -> 0
D29: LESS: CREDIT ORIGINATED BY BOG BUT NOT DEBITED IN OUR BOOKS
D32: TOTAL: | E32: =SUM($E$30:$E$31) -> 0
D35: LESS: CREDIT IN OUR BOOKS BUT NOT DEBITED BY BOG
D38: TOTAL: | E38: =SUM($E$36:$E$37) -> 0
D41: GRAND TOTAL | E41: =ABS(E13+$E$20-$E$38+$E$26-$E$32) -> 104537.49
D42: INTERNAL ACCOUNT BALANCE AS AT Nov 20, 2025 | E42: 104537.49 | I42: DR
D43: DIFFERENCE | E43: =$E$42-$E$41 -> 0
D45: PREPARED BY: | E45: Ebenezer Frimpong | F45: DATE: | G45: 45981
D48: REVIEWED BY: | F48: DATE:

Sheet BOG KSI GHS
A1: Field_1 | B1: Field_2 | C1: Field_3 | D1: Field_4 | E1: Field_5 | F1: Field_6 | G1: Field_7 | H1: Field_8 | I1: Field_9 | J1: Field_10
B4: DEPT | D4: OPERATIONS | E4: BANK ACCOUNT NUMBER | F4: 2017231344017
B6: BRANCH | D6: HEAD OFFICE | E6: GENERAL LEDGER NAME | F6: BANK OF GHANA -KUMASI-GHS
B8: REPORTING DATE | D8: 20-Nov-25 | E8: GENERAL LEDGER NUMBER | F8: 0010113040010
B10: REPORTING UNIT | D10: RECONCILIATION
C13: 20-Nov-2025 | D13: BALANCE PER BANK STATEMENT | E13: 7025754.9 | I13: CR
B15: SN | C15: DATE | D15: DESCRIPTION | E15: AMOUNT | F15: GL Ref No. | G15: AGING(DAYS) | H15: RECON
D17: ADD: DEBIT IN OUR BOOKS BUT NOT CREDITED BY BOG
D20: TOTAL: | E20: =SUM($E$18:$E$19) -> 0
D23: ADD: DEBIT ORIGINATED BY BOG BUT NOT CREDITED IN OUR BOOKS
D26: TOTAL: | E26: =SUM($E$24:$E$25) -> 0
D29: LESS: CREDIT ORIGINATED BY BOG BUT NOT DEBITED IN OUR BOOKS
D32: TOTAL: | E32: =SUM($E$30:$E$31) -> 0
D35: LESS: CREDIT IN OUR BOOKS BUT NOT DEBITED BY BOG
D38: TOTAL: | E38: =SUM($E$36:$E$37) -> 0
D41: GRAND TOTAL | E41: =ABS(E13+$E$20-$E$38+$E$26-$E$32) -> 7025754.9
D42: INTERNAL ACCOUNT BALANCE AS AT Nov 20, 2025 | E42: 7025754.9 | I42: DR
D43: DIFFERENCE | E43: =$E$42-$E$41 -> 0
D45: PREPARED BY: | E45: kenneth nuamah | F45: DATE: | G45: 45981
D48: REVIEWED BY: | F48: DATE:

Sheet BOG KSI USD
A1: Field_1 | B1: Field_2 | C1: Field_3 | D1: Field_4 | E1: Field_5 | F1: Field_6 | G1: Field_7 | H1: Field_8 | I1: Field_9 | J1: Field_10
B4: DEPT | D4: OPERATIONS | E4: BANK ACCOUNT NUMBER | F4: 2027231344015
B6: BRANCH | D6: HEAD OFFICE | E6: GENERAL LEDGER NAME | F6: BANK OF GHANA -KUMASI-USD
B8: REPORTING DATE | D8: 20-Nov-25 | E8: GENERAL LEDGER NUMBER | F8: 0020113040018
B10: REPORTING UNIT | D10: RECONCILIATION
C13: 2025-10-31 | D13: BALANCE PER BANK STATEMENT | E13: 1103000 | I13: CR
B15: SN | C15: DATE | D15: DESCRIPTION | E15: AMOUNT | F15: GL Ref No. | G15: AGING(DAYS) | H15: RECON
D17: ADD: DEBIT IN OUR BOOKS BUT NOT CREDITED BY BOG
D20: TOTAL: | E20: =SUM($E$18:$E$19) -> 0
D23: ADD: DEBIT ORIGINATED BY BOG BUT NOT CREDITED IN OUR BOOKS
D26: TOTAL: | E26: =SUM($E$24:$E$25) -> 0
D29: LESS: CREDIT ORIGINATED BY BOG BUT NOT DEBITED IN OUR BOOKS
D32: TOTAL: | E32: =SUM($E$30:$E$31) -> 0
D35: LESS: CREDIT IN OUR BOOKS BUT NOT DEBITED BY BOG
D38: TOTAL: | E38: =SUM($E$36:$E$37) -> 0
D41: GRAND TOTAL | E41: =ABS(E13+$E$20-$E$38+$E$26-$E$32) -> 1103000
D42: INTERNAL ACCOUNT BALANCE AS AT Nov 20, 2025 | E42: 1103000 | I42: DR
D43: DIFFERENCE | E43: =$E$42-$E$41 -> 0
D45: PREPARED BY: | E45: kenneth nuamah | F45: DATE: | G45: 45981
D48: REVIEWED BY: | F48: DATE:

Sheet BOG KSI EUR
A1: Field_1 | B1: Field_2 | C1: Field_3 | D1: Field_4 | E1: Field_5 | F1: Field_6 | G1: Field_7 | H1: Field_8 | I1: Field_9 | J1: Field_10
B4: DEPT | D4: OPERATIONS | E4: BANK ACCOUNT NUMBER | F4: 2187231344012
B6: BRANCH | D6: HEAD OFFICE | E6: GENERAL LEDGER NAME | F6: BANK OF GHANA -KUMASI-EUR
B8: REPORTING DATE | D8: 20-Nov-25 | E8: GENERAL LEDGER NUMBER | F8: 0030113040015
B10: REPORTING UNIT | D10: RECONCILIATION
C13: 2025-10-31 | D13: BALANCE PER BANK STATEMENT | E13: 260500 | I13: CR
B15: SN | C15: DATE | D15: DESCRIPTION | E15: AMOUNT | F15: GL Ref No. | G15: AGING(DAYS) | H15: RECON
D17: ADD: DEBIT IN OUR BOOKS BUT NOT CREDITED BY BOG
D20: TOTAL: | E20: =SUM($E$18:$E$19) -> 0
D23: ADD: DEBIT ORIGINATED BY BOG BUT NOT CREDITED IN OUR BOOKS
D26: TOTAL: | E26: =SUM($E$24:$E$25) -> 0
D29: LESS: CREDIT ORIGINATED BY BOG BUT NOT DEBITED IN OUR BOOKS
D32: TOTAL: | E32: =SUM($E$30:$E$31) -> 0
D35: LESS: CREDIT IN OUR BOOKS BUT NOT DEBITED BY BOG
D38: TOTAL: | E38: =SUM($E$36:$E$37) -> 0
D41: GRAND TOTAL | E41: =ABS(E13+$E$20-$E$38+$E$26-$E$32) -> 260500
D42: INTERNAL ACCOUNT BALANCE AS AT Nov 20, 2025 | E42: 260500 | I42: DR
D43: DIFFERENCE | E43: =$E$42-$E$41 -> 0
D45: PREPARED BY: | E45: kenneth nuamah | F45: DATE: | G45: 45981
D48: REVIEWED BY: | F48: DATE:

Sheet BOG KSI GBP
A1: Field_1 | B1: Field_2 | C1: Field_3 | D1: Field_4 | E1: Field_5 | F1: Field_6 | G1: Field_7 | H1: Field_8 | I1: Field_9 | J1: Field_10
B4: DEPT | D4: OPERATIONS | E4: BANK ACCOUNT NUMBER | F4: 2037231344018
B6: BRANCH | D6: HEAD OFFICE | E6: GENERAL LEDGER NAME | F6: BANK OF GHANA -KUMASI-GBP
B8: REPORTING DATE | D8: 20-Nov-25 | E8: GENERAL LEDGER NUMBER | F8: 0040113040012
B10: REPORTING UNIT | D10: RECONCILIATION
C13: 2025-10-31 | D13: BALANCE PER BANK STATEMENT | E13: 48843.2 | I13: CR
B15: SN | C15: DATE | D15: DESCRIPTION | E15: AMOUNT | F15: GL Ref No. | G15: AGING(DAYS) | H15: RECON
D17: ADD: DEBIT IN OUR BOOKS BUT NOT CREDITED BY BOG
D20: TOTAL: | E20: =SUM($E$18:$E$19) -> 0
D23: ADD: DEBIT ORIGINATED BY BOG BUT NOT CREDITED IN OUR BOOKS
D26: TOTAL: | E26: =SUM($E$24:$E$25) -> 0
D29: LESS: CREDIT ORIGINATED BY BOG BUT NOT DEBITED IN OUR BOOKS
D32: TOTAL: | E32: =SUM($E$30:$E$31) -> 0
D35: LESS: CREDIT IN OUR BOOKS BUT NOT DEBITED BY BOG
D38: TOTAL: | E38: =SUM($E$36:$E$37) -> 0
D41: GRAND TOTAL | E41: =ABS(E13+$E$20-$E$38+$E$26-$E$32) -> 48843.2
D42: INTERNAL ACCOUNT BALANCE AS AT Nov 20, 2025 | E42: 48843.2 | I42: DR
D43: DIFFERENCE | E43: =$E$42-$E$41 -> 0
D45: PREPARED BY: | E45: kenneth nuamah | F45: DATE: | G45: 45981
D48: REVIEWED BY: | F48: DATE:

Sheet BOG SYI GHS
A1: Field_1 | B1: Field_2 | C1: Field_3 | D1: Field_4 | E1: Field_5 | F1: Field_6 | G1: Field_7 | H1: Field_8 | I1: Field_9 | J1: Field_10
B4: DEPT | D4: OPERATIONS | E4: BANK ACCOUNT NUMBER | F4: 4017131344017
B6: BRANCH | D6: HEAD OFFICE | E6: GENERAL LEDGER NAME | F6: BANK OF GHANA -SUNYANI-GHS
B8: REPORTING DATE | D8: 20-Nov-25 | E8: GENERAL LEDGER NUMBER | F8: 0010086657018
B10: REPORTING UNIT | D10: RECONCILIATION
C13: 19-Nov-2025 | D13: BALANCE PER BANK STATEMENT | E13: 46082773 | I13: CR
B15: SN | C15: DATE | D15: DESCRIPTION | E15: AMOUNT | F15: GL Ref No. | G15: AGING(DAYS) | H15: RECON
D17: ADD: DEBIT IN OUR BOOKS BUT NOT CREDITED BY BOG
D20: TOTAL: | E20: =SUM($E$18:$E$19) -> 0
D23: ADD: DEBIT ORIGINATED BY BOG BUT NOT CREDITED IN OUR BOOKS
D26: TOTAL: | E26: =SUM($E$24:$E$25) -> 0
D29: LESS: CREDIT ORIGINATED BY BOG BUT NOT DEBITED IN OUR BOOKS
D32: TOTAL: | E32: =SUM($E$30:$E$31) -> 0
D35: LESS: CREDIT IN OUR BOOKS BUT NOT DEBITED BY BOG
D38: TOTAL: | E38: =SUM($E$36:$E$37) -> 0
D41: GRAND TOTAL | E41: =ABS(E13+$E$20-$E$38+$E$26-$E$32) -> 46082773
D42: INTERNAL ACCOUNT BALANCE AS AT Nov 20, 2025 | E42: 46082773 | I42: DR
D43: DIFFERENCE | E43: =$E$42-$E$41 -> 0
D45: PREPARED BY: | E45: kenneth nuamah | F45: DATE: | G45: 45981
D48: REVIEWED BY: | F48: DATE:

Sheet BOG SYI USD
A1: Field_1 | B1: Field_2 | C1: Field_3 | D1: Field_4 | E1: Field_5 | F1: Field_6 | G1: Field_7 | H1: Field_8 | I1: Field_9 | J1: Field_10
B4: DEPT | D4: OPERATIONS | E4: BANK ACCOUNT NUMBER | F4: 4027231344012
B6: BRANCH | D6: HEAD OFFICE | E6: GENERAL LEDGER NAME | F6: BANK OF GHANA -SUNYANI-USD
B8: REPORTING DATE | D8: 20-Nov-25 | E8: GENERAL LEDGER NUMBER | F8: 0020086657015
B10: REPORTING UNIT | D10: RECONCILIATION
C13: 2025-10-31 | D13: BALANCE PER BANK STATEMENT | E13: 30000 | I13: CR
B15: SN | C15: DATE | D15: DESCRIPTION | E15: AMOUNT | F15: GL Ref No. | G15: AGING(DAYS) | H15: RECON
D17: ADD: DEBIT IN OUR BOOKS BUT NOT CREDITED BY BOG
D20: TOTAL: | E20: =SUM($E$18:$E$19) -> 0
D23: ADD: DEBIT ORIGINATED BY BOG BUT NOT CREDITED IN OUR BOOKS
D26: TOTAL: | E26: =SUM($E$24:$E$25) -> 0
D29: LESS: CREDIT ORIGINATED BY BOG BUT NOT DEBITED IN OUR BOOKS
D32: TOTAL: | E32: =SUM($E$30:$E$31) -> 0
D35: LESS: CREDIT IN OUR BOOKS BUT NOT DEBITED BY BOG
D38: TOTAL: | E38: =SUM($E$36:$E$37) -> 0
D41: GRAND TOTAL | E41: =ABS(E13+$E$20-$E$38+$E$26-$E$32) -> 30000
D42: INTERNAL ACCOUNT BALANCE AS AT Nov 20, 2025 | E42: 30000 | I42: DR
D43: DIFFERENCE | E43: =$E$42-$E$41 -> 0
D45: PREPARED BY: | E45: kenneth nuamah | F45: DATE: | G45: 45981
D48: REVIEWED BY: | F48: DATE:

Sheet BOG SYI EUR
A1: Field_1 | B1: Field_2 | C1: Field_3 | D1: Field_4 | E1: Field_5 | F1: Field_6 | G1: Field_7 | H1: Field_8 | I1: Field_9 | J1: Field_10
B4: DEPT | D4: OPERATIONS | E4: BANK ACCOUNT NUMBER | F4: 4027231344012
B6: BRANCH | D6: HEAD OFFICE | E6: GENERAL LEDGER NAME | F6: BANK OF GHANA -SUNYANI-EUR
B8: REPORTING DATE | D8: 20-Nov-25 | E8: GENERAL LEDGER NUMBER | F8: 0020086657015
B10: REPORTING UNIT | D10: RECONCILIATION
C13: 2025-10-31 | D13: BALANCE PER BANK STATEMENT | E13: 0 | I13: CR
B15: SN | C15: DATE | D15: DESCRIPTION | E15: AMOUNT | F15: GL Ref No. | G15: AGING(DAYS) | H15: RECON
D17: ADD: DEBIT IN OUR BOOKS BUT NOT CREDITED BY BOG
D20: TOTAL: | E20: =SUM($E$18:$E$19) -> 0
D23: ADD: DEBIT ORIGINATED BY BOG BUT NOT CREDITED IN OUR BOOKS
D26: TOTAL: | E26: =SUM($E$24:$E$25) -> 0
D29: LESS: CREDIT ORIGINATED BY BOG BUT NOT DEBITED IN OUR BOOKS
D32: TOTAL: | E32: =SUM($E$30:$E$31) -> 0
D35: LESS: CREDIT IN OUR BOOKS BUT NOT DEBITED BY BOG
D38: TOTAL: | E38: =SUM($E$36:$E$37) -> 0
D41: GRAND TOTAL | E41: =ABS(E13+$E$20-$E$38+$E$26-$E$32) -> 0
D42: INTERNAL ACCOUNT BALANCE AS AT Nov 20, 2025 | E42: 0 | I42: DR
D43: DIFFERENCE | E43: =$E$42-$E$41 -> 0
D45: PREPARED BY: | E45: kenneth nuamah | F45: DATE: | G45: 45981
D48: REVIEWED BY: | F48: DATE:

Sheet BOG SYI GBP
A1: Field_1 | B1: Field_2 | C1: Field_3 | D1: Field_4 | E1: Field_5 | F1: Field_6 | G1: Field_7 | H1: Field_8 | I1: Field_9 | J1: Field_10
B4: DEPT | D4: OPERATIONS | E4: BANK ACCOUNT NUMBER | F4: 4027231344012
B6: BRANCH | D6: HEAD OFFICE | E6: GENERAL LEDGER NAME | F6: BANK OF GHANA -SUNYANI-GBP
B8: REPORTING DATE | D8: 20-Nov-25 | E8: GENERAL LEDGER NUMBER | F8: 0020086657015
B10: REPORTING UNIT | D10: RECONCILIATION
C13: 2025-10-31 | D13: BALANCE PER BANK STATEMENT | E13: 0 | I13: CR
B15: SN | C15: DATE | D15: DESCRIPTION | E15: AMOUNT | F15: GL Ref No. | G15: AGING(DAYS) | H15: RECON
D17: ADD: DEBIT IN OUR BOOKS BUT NOT CREDITED BY BOG
D20: TOTAL: | E20: =SUM($E$18:$E$19) -> 0
D23: ADD: DEBIT ORIGINATED BY BOG BUT NOT CREDITED IN OUR BOOKS
D26: TOTAL: | E26: =SUM($E$24:$E$25) -> 0
D29: LESS: CREDIT ORIGINATED BY BOG BUT NOT DEBITED IN OUR BOOKS
D32: TOTAL: | E32: =SUM($E$30:$E$31) -> 0
D35: LESS: CREDIT IN OUR BOOKS BUT NOT DEBITED BY BOG
D38: TOTAL: | E38: =SUM($E$36:$E$37) -> 0
D41: GRAND TOTAL | E41: =ABS(E13+$E$20-$E$38+$E$26-$E$32) -> 0
D42: INTERNAL ACCOUNT BALANCE AS AT Nov 20, 2025 | E42: 0 | I42: DR
D43: DIFFERENCE | E43: =$E$42-$E$41 -> 0
D45: PREPARED BY: | E45: kenneth nuamah | F45: DATE: | G45: 45981
D48: REVIEWED BY: | F48: DATE:

Sheet BOG TDI GHS
A1: Field_1 | B1: Field_2 | C1: Field_3 | D1: Field_4 | E1: Field_5 | F1: Field_6 | G1: Field_7 | H1: Field_8 | I1: Field_9 | J1: Field_10
B4: DEPT | D4: OPERATIONS | E4: BANK ACCOUNT NUMBER | F4: 3017231344013
B6: BRANCH | D6: HEAD OFFICE | E6: GENERAL LEDGER NAME | F6: BANK OF GHANA -TAKORADI-GHS
B8: REPORTING DATE | D8: 20-Nov-25 | E8: GENERAL LEDGER NUMBER | F8: 0010113730019
B10: REPORTING UNIT | D10: RECONCILIATION
C13: 19-Nov-2025 | D13: BALANCE PER BANK STATEMENT | E13: 6801989 | I13: CR
B15: SN | C15: DATE | D15: DESCRIPTION | E15: AMOUNT | F15: GL Ref No. | G15: AGING(DAYS) | H15: RECON
D17: ADD: DEBIT IN OUR BOOKS BUT NOT CREDITED BY BOG
D20: TOTAL: | E20: =SUM($E$18:$E$19) -> 0
D23: ADD: DEBIT ORIGINATED BY BOG BUT NOT CREDITED IN OUR BOOKS
D26: TOTAL: | E26: =SUM($E$24:$E$25) -> 0
D29: LESS: CREDIT ORIGINATED BY BOG BUT NOT DEBITED IN OUR BOOKS
D32: TOTAL: | E32: =SUM($E$30:$E$31) -> 0
D35: LESS: CREDIT IN OUR BOOKS BUT NOT DEBITED BY BOG
D38: TOTAL: | E38: =SUM($E$36:$E$37) -> 0
D41: GRAND TOTAL | E41: =ABS(E13+$E$20-$E$38+$E$26-$E$32) -> 6801989
D42: INTERNAL ACCOUNT BALANCE AS AT Nov 20, 2025 | E42: 6801989 | I42: DR
D43: DIFFERENCE | E43: =$E$42-$E$41 -> 0
D45: PREPARED BY: | E45: kenneth nuamah | F45: DATE: | G45: 45981
D48: REVIEWED BY: | F48: DATE:

Sheet BOG TDI USD
A1: Field_1 | B1: Field_2 | C1: Field_3 | D1: Field_4 | E1: Field_5 | F1: Field_6 | G1: Field_7 | H1: Field_8 | I1: Field_9 | J1: Field_10
B4: DEPT | D4: OPERATIONS | E4: BANK ACCOUNT NUMBER | F4: 3027231344019
B6: BRANCH | D6: HEAD OFFICE | E6: GENERAL LEDGER NAME | F6: BANK OF GHANA -TAKORADI-USD
B8: REPORTING DATE | D8: 20-Nov-25 | E8: GENERAL LEDGER NUMBER | F8: 0020113730016
B10: REPORTING UNIT | D10: RECONCILIATION
C13: 2025-11-11 | D13: BALANCE PER BANK STATEMENT | E13: 72200 | I13: CR
B15: SN | C15: DATE | D15: DESCRIPTION | E15: AMOUNT | F15: GL Ref No. | G15: AGING(DAYS) | H15: RECON
D17: ADD: DEBIT IN OUR BOOKS BUT NOT CREDITED BY BOG
D20: TOTAL: | E20: =SUM($E$18:$E$19) -> 0
D23: ADD: DEBIT ORIGINATED BY BOG BUT NOT CREDITED IN OUR BOOKS
D26: TOTAL: | E26: =SUM($E$24:$E$25) -> 0
D29: LESS: CREDIT ORIGINATED BY BOG BUT NOT DEBITED IN OUR BOOKS
D32: TOTAL: | E32: =SUM($E$30:$E$31) -> 0
D35: LESS: CREDIT IN OUR BOOKS BUT NOT DEBITED BY BOG
D38: TOTAL: | E38: =SUM($E$36:$E$37) -> 0
D41: GRAND TOTAL | E41: =ABS(E13+$E$20-$E$38+$E$26-$E$32) -> 72200
D42: INTERNAL ACCOUNT BALANCE AS AT Nov 20, 2025 | E42: 72200 | I42: DR
D43: DIFFERENCE | E43: =$E$42-$E$41 -> 0
D45: PREPARED BY: | E45: kenneth nuamah | F45: DATE: | G45: 45981
D48: REVIEWED BY: | F48: DATE:

Sheet BOG TDI EUR
A1: Field_1 | B1: Field_2 | C1: Field_3 | D1: Field_4 | E1: Field_5 | F1: Field_6 | G1: Field_7 | H1: Field_8 | I1: Field_9 | J1: Field_10
B4: DEPT | D4: OPERATIONS | E4: BANK ACCOUNT NUMBER | F4: 3187231344016
B6: BRANCH | D6: HEAD OFFICE | E6: GENERAL LEDGER NAME | F6: BANK OF GHANA -TAKORADI- EUR
B8: REPORTING DATE | D8: 20-Nov-25 | E8: GENERAL LEDGER NUMBER | F8: 0030113730013
B10: REPORTING UNIT | D10: RECONCILIATION
C13: 2025-11-11 | D13: BALANCE PER BANK STATEMENT | E13: 159835 | I13: CR
B15: SN | C15: DATE | D15: DESCRIPTION | E15: AMOUNT | F15: GL Ref No. | G15: AGING(DAYS) | H15: RECON
D17: ADD: DEBIT IN OUR BOOKS BUT NOT CREDITED BY BOG
D20: TOTAL: | E20: =SUM($E$18:$E$19) -> 0
D23: ADD: DEBIT ORIGINATED BY BOG BUT NOT CREDITED IN OUR BOOKS
D26: TOTAL: | E26: =SUM($E$24:$E$25) -> 0
D29: LESS: CREDIT ORIGINATED BY BOG BUT NOT DEBITED IN OUR BOOKS
D32: TOTAL: | E32: =SUM($E$30:$E$31) -> 0
D35: LESS: CREDIT IN OUR BOOKS BUT NOT DEBITED BY BOG
D38: TOTAL: | E38: =SUM($E$36:$E$37) -> 0
D41: GRAND TOTAL | E41: =ABS(E13+$E$20-$E$38+$E$26-$E$32) -> 159835
D42: INTERNAL ACCOUNT BALANCE AS AT Nov 20, 2025 | E42: 159835 | I42: DR
D43: DIFFERENCE | E43: =$E$42-$E$41 -> 0
D45: PREPARED BY: | E45: kenneth nuamah | F45: DATE: | G45: 45981
D48: REVIEWED BY: | F48: DATE:

Sheet BOG TDI GBP
A1: Field_1 | B1: Field_2 | C1: Field_3 | D1: Field_4 | E1: Field_5 | F1: Field_6 | G1: Field_7 | H1: Field_8 | I1: Field_9 | J1: Field_10
B4: DEPT | D4: OPERATIONS | E4: BANK ACCOUNT NUMBER | F4: 3037231344014
B6: BRANCH | D6: HEAD OFFICE | E6: GENERAL LEDGER NAME | F6: BANK OF GHANA -TAKORADI- GBP
B8: REPORTING DATE | D8: 20-Nov-25 | E8: GENERAL LEDGER NUMBER | F8: 0040113730010
B10: REPORTING UNIT | D10: RECONCILIATION
C13: 2025-10-31 | D13: BALANCE PER BANK STATEMENT | E13: 14340 | I13: CR
B15: SN | C15: DATE | D15: DESCRIPTION | E15: AMOUNT | F15: GL Ref No. | G15: AGING(DAYS) | H15: RECON
D17: ADD: DEBIT IN OUR BOOKS BUT NOT CREDITED BY BOG
D20: TOTAL: | E20: =SUM($E$18:$E$19) -> 0
D23: ADD: DEBIT ORIGINATED BY BOG BUT NOT CREDITED IN OUR BOOKS
D26: TOTAL: | E26: =SUM($E$24:$E$25) -> 0
D29: LESS: CREDIT ORIGINATED BY BOG BUT NOT DEBITED IN OUR BOOKS
D32: TOTAL: | E32: =SUM($E$30:$E$31) -> 0
D35: LESS: CREDIT IN OUR BOOKS BUT NOT DEBITED BY BOG
D38: TOTAL: | E38: =SUM($E$36:$E$37) -> 0
D41: GRAND TOTAL | E41: =ABS(E13+$E$20-$E$38+$E$26-$E$32) -> 14340
D42: INTERNAL ACCOUNT BALANCE AS AT Nov 20, 2025 | E42: 14340 | I42: DR
D43: DIFFERENCE | E43: =$E$42-$E$41 -> 0
D45: PREPARED BY: | E45: kenneth nuamah | F45: DATE: | G45: 45981
D48: REVIEWED BY: | F48: DATE:

Sheet BOG TLE GHS
A1: Field_1 | B1: Field_2 | C1: Field_3 | D1: Field_4 | E1: Field_5 | F1: Field_6 | G1: Field_7 | H1: Field_8 | I1: Field_9 | J1: Field_10
B4: DEPT | D4: OPERATIONS | E4: BANK ACCOUNT NUMBER | F4: 5017231344018
B6: BRANCH | D6: HEAD OFFICE | E6: GENERAL LEDGER NAME | F6: BANK OF GHANA -TAMALE-GHS
B8: REPORTING DATE | D8: 20-Nov-25 | E8: GENERAL LEDGER NUMBER | F8: 0010000092019
B10: REPORTING UNIT | D10: RECONCILIATION
C13: 20-Nov-2025 | D13: BALANCE PER BANK STATEMENT | E13: 34296332 | I13: CR
B15: SN | C15: DATE | D15: DESCRIPTION | E15: AMOUNT | F15: GL Ref No. | G15: AGING(DAYS) | H15: RECON
D17: ADD: DEBIT IN OUR BOOKS BUT NOT CREDITED BY BOG
D20: TOTAL: | E20: =SUM($E$18:$E$19) -> 0
D23: ADD: DEBIT ORIGINATED BY BOG BUT NOT CREDITED IN OUR BOOKS
D26: TOTAL: | E26: =SUM($E$24:$E$25) -> 0
D29: LESS: CREDIT ORIGINATED BY BOG BUT NOT DEBITED IN OUR BOOKS
D32: TOTAL: | E32: =SUM($E$30:$E$31) -> 0
D35: LESS: CREDIT IN OUR BOOKS BUT NOT DEBITED BY BOG
D38: TOTAL: | E38: =SUM($E$36:$E$37) -> 0
D41: GRAND TOTAL | E41: =ABS(E13+$E$20-$E$38+$E$26-$E$32) -> 34296332
D42: INTERNAL ACCOUNT BALANCE AS AT Nov 20, 2025 | E42: 34296332 | I42: DR
D43: DIFFERENCE | E43: =$E$42-$E$41 -> 0
D45: PREPARED BY: | E45: kenneth nuamah | F45: DATE: | G45: 45981
D48: REVIEWED BY: | F48: DATE:

Sheet BOG TLE USD
A1: Field_1 | B1: Field_2 | C1: Field_3 | D1: Field_4 | E1: Field_5 | F1: Field_6 | G1: Field_7 | H1: Field_8 | I1: Field_9 | J1: Field_10
B4: DEPT | D4: OPERATIONS | E4: BANK ACCOUNT NUMBER | F4: 5027231344016
B6: BRANCH | D6: HEAD OFFICE | E6: GENERAL LEDGER NAME | F6: BANK OF GHANA -TAMALE-USD
B8: REPORTING DATE | D8: 20-Nov-25 | E8: GENERAL LEDGER NUMBER | F8: 0020000092016
B10: REPORTING UNIT | D10: RECONCILIATION
C13: 14-Nov-2025 | D13: BALANCE PER BANK STATEMENT | E13: 76000 | I13: CR
B15: SN | C15: DATE | D15: DESCRIPTION | E15: AMOUNT | F15: GL Ref No. | G15: AGING(DAYS) | H15: RECON
D17: ADD: DEBIT IN OUR BOOKS BUT NOT CREDITED BY BOG
D20: TOTAL: | E20: =SUM($E$18:$E$19) -> 0
D23: ADD: DEBIT ORIGINATED BY BOG BUT NOT CREDITED IN OUR BOOKS
D26: TOTAL: | E26: =SUM($E$24:$E$25) -> 0
D29: LESS: CREDIT ORIGINATED BY BOG BUT NOT DEBITED IN OUR BOOKS
D32: TOTAL: | E32: =SUM($E$30:$E$31) -> 0
D35: LESS: CREDIT IN OUR BOOKS BUT NOT DEBITED BY BOG
D38: TOTAL: | E38: =SUM($E$36:$E$37) -> 0
D41: GRAND TOTAL | E41: =ABS(E13+$E$20-$E$38+$E$26-$E$32) -> 76000
D42: INTERNAL ACCOUNT BALANCE AS AT Nov 20, 2025 | E42: 76000 | I42: DR
D43: DIFFERENCE | E43: =$E$42-$E$41 -> 0
D45: PREPARED BY: | E45: kenneth nuamah | F45: DATE: | G45: 45981
D48: REVIEWED BY: | F48: DATE:

Sheet BOG TLE EUR
A1: Field_1 | B1: Field_2 | C1: Field_3 | D1: Field_4 | E1: Field_5 | F1: Field_6 | G1: Field_7 | H1: Field_8 | I1: Field_9 | J1: Field_10
B4: DEPT | D4: OPERATIONS | E4: BANK ACCOUNT NUMBER | F4: 5187231344013
B6: BRANCH | D6: HEAD OFFICE | E6: GENERAL LEDGER NAME | F6: BANK OF GHANA -TAMALE-EUR
B8: REPORTING DATE | D8: 20-Nov-25 | E8: GENERAL LEDGER NUMBER | F8: 0030000092013
B10: REPORTING UNIT | D10: RECONCILIATION
C13: 14-Nov-2025 | D13: BALANCE PER BANK STATEMENT | E13: 500 | I13: CR
B15: SN | C15: DATE | D15: DESCRIPTION | E15: AMOUNT | F15: GL Ref No. | G15: AGING(DAYS) | H15: RECON
D17: ADD: DEBIT IN OUR BOOKS BUT NOT CREDITED BY BOG
D20: TOTAL: | E20: =SUM($E$18:$E$19) -> 0
D23: ADD: DEBIT ORIGINATED BY BOG BUT NOT CREDITED IN OUR BOOKS
D26: TOTAL: | E26: =SUM($E$24:$E$25) -> 0
D29: LESS: CREDIT ORIGINATED BY BOG BUT NOT DEBITED IN OUR BOOKS
D32: TOTAL: | E32: =SUM($E$30:$E$31) -> 0
D35: LESS: CREDIT IN OUR BOOKS BUT NOT DEBITED BY BOG
D38: TOTAL: | E38: =SUM($E$36:$E$37) -> 0
D41: GRAND TOTAL | E41: =ABS(E13+$E$20-$E$38+$E$26-$E$32) -> 500
D42: INTERNAL ACCOUNT BALANCE AS AT Nov 20, 2025 | E42: 500 | I42: DR
D43: DIFFERENCE | E43: =$E$42-$E$41 -> 0
D45: PREPARED BY: | E45: kenneth nuamah | F45: DATE: | G45: 45981
D48: REVIEWED BY: | F48: DATE:

Sheet BOG TLE GBP
A1: Field_1 | B1: Field_2 | C1: Field_3 | D1: Field_4 | E1: Field_5 | F1: Field_6 | G1: Field_7 | H1: Field_8 | I1: Field_9 | J1: Field_10
B4: DEPT | D4: OPERATIONS | E4: BANK ACCOUNT NUMBER | F4: 5187231344013
B6: BRANCH | D6: HEAD OFFICE | E6: GENERAL LEDGER NAME | F6: BANK OF GHANA -TAMALE-GBP
B8: REPORTING DATE | D8: 20-Nov-25 | E8: GENERAL LEDGER NUMBER | F8: 0030000092013
B10: REPORTING UNIT | D10: RECONCILIATION
C13: 2025-11-12 | D13: BALANCE PER BANK STATEMENT | E13: 0 | I13: CR
B15: SN | C15: DATE | D15: DESCRIPTION | E15: AMOUNT | F15: GL Ref No. | G15: AGING(DAYS) | H15: RECON
D17: ADD: DEBIT IN OUR BOOKS BUT NOT CREDITED BY BOG
D20: TOTAL: | E20: =SUM($E$18:$E$19) -> 0
D23: ADD: DEBIT ORIGINATED BY BOG BUT NOT CREDITED IN OUR BOOKS
D26: TOTAL: | E26: =SUM($E$24:$E$25) -> 0
D29: LESS: CREDIT ORIGINATED BY BOG BUT NOT DEBITED IN OUR BOOKS
D32: TOTAL: | E32: =SUM($E$30:$E$31) -> 0
D35: LESS: CREDIT IN OUR BOOKS BUT NOT DEBITED BY BOG
D38: TOTAL: | E38: =SUM($E$36:$E$37) -> 0
D41: GRAND TOTAL | E41: =ABS(E13+$E$20-$E$38+$E$26-$E$32) -> 0
D42: INTERNAL ACCOUNT BALANCE AS AT Nov 20, 2025 | E42: 0 | I42: DR
D43: DIFFERENCE | E43: =$E$42-$E$41 -> 0
D45: PREPARED BY: | E45: kenneth nuamah | F45: DATE: | G45: 45981
D48: REVIEWED BY: | F48: DATE:

Sheet AFRIEXIM EUR
A1: Field_1 | B1: Field_2 | C1: Field_3 | D1: Field_4 | E1: Field_5 | F1: Field_6 | G1: Field_7 | H1: Field_8 | I1: FIELD_9
B4: DEPT | D4: OPERATIONS | E4: BANK ACCOUNT NUMBER | F4: 300058801200001
B6: BRANCH | D6: HEAD OFFICE | E6: GENERAL LEDGER NAME | F6: AFRIEXIM EUR
B8: REPORTING DATE | D8: 20-Nov-25 | E8: GENERAL LEDGER NUMBER | F8: 0030000097017
B10: REPORTING UNIT | D10: RECONCILIATION
C13: 20-Nov-25 | D13: BALANCE PER BANK STATEMENT | E13: 0 | I13: DR
B15: SN | C15: DATE | D15: DESCRIPTION | E15: AMOUNT | F15: GL Ref No. | G15: AGING(DAYS) | H15: RECON
D17: ADD: DEBIT IN OUR BOOKS BUT NOT CREDITED BY AFRIEXIM
D20: TOTAL: | E20: =SUM($E$18:$E$19) -> 0
D23: ADD: DEBIT ORIGINATED BY AFRIEXIM BUT NOT CREDITED IN OUR BOOKS
D26: TOTAL: | E26: =SUM($E$24:$E$25) -> 0
D29: LESS: CREDIT ORIGINATED BY AFRIEXIM BUT NOT DEBITED IN OUR BOOKS
D32: TOTAL: | E32: =SUM($E$30:$E$31) -> 0
D35: LESS: CREDIT IN OUR BOOKS BUT NOT DEBITED BY AFRIEXIM
D38: TOTAL: | E38: =SUM($E$36:$E$37) -> 0
D41: GRAND TOTAL | E41: =ABS(E13+$E$20-$E$38+$E$26-$E$32) -> 0
D42: INTERNAL ACCOUNT BALANCE AS AT Nov 20, 2025 | E42: 0 | I42: DR
D43: DIFFERENCE | E43: =$E$42-$E$41 -> 0
D45: PREPARED BY: | E45: kenneth nuamah | F45: DATE: | G45: 45981
D48: REVIEWED BY: | F48: DATE:

Sheet AFRIEXIM GBP
A1: Field_1 | B1: Field_2 | C1: Field_3 | D1: Field_4 | E1: Field_5 | F1: Field_6 | G1: Field_7 | H1: Field_8 | I1: FIELD_9
B4: DEPT | D4: OPERATIONS | E4: BANK ACCOUNT NUMBER | F4: 300058801200001
B6: BRANCH | D6: HEAD OFFICE | E6: GENERAL LEDGER NAME | F6: AFRIEXIM GBP
B8: REPORTING DATE | D8: 20-Nov-25 | E8: GENERAL LEDGER NUMBER | F8: 0040000097014
B10: REPORTING UNIT | D10: RECONCILIATION
C13: 20-Nov-25 | D13: BALANCE PER BANK STATEMENT | E13: 2313 | I13: CR
B15: SN | C15: DATE | D15: DESCRIPTION | E15: AMOUNT | F15: GL Ref No. | G15: AGING(DAYS) | H15: RECON
D17: ADD: DEBIT IN OUR BOOKS BUT NOT CREDITED BY AFRIEXIM
D20: TOTAL: | E20: =SUM($E$18:$E$19) -> 0
D23: ADD: DEBIT ORIGINATED BY AFRIEXIM BUT NOT CREDITED IN OUR BOOKS
D26: TOTAL: | E26: =SUM($E$24:$E$25) -> 0
D29: LESS: CREDIT ORIGINATED BY AFRIEXIM BUT NOT DEBITED IN OUR BOOKS
D32: TOTAL: | E32: =SUM($E$30:$E$31) -> 0
D35: LESS: CREDIT IN OUR BOOKS BUT NOT DEBITED BY AFRIEXIM
D38: TOTAL: | E38: =SUM($E$36:$E$37) -> 0
D41: GRAND TOTAL | E41: =ABS(E13+$E$20-$E$38+$E$26-$E$32) -> 2313
D42: INTERNAL ACCOUNT BALANCE AS AT Nov 20, 2025 | E42: 2313 | I42: CR
D43: DIFFERENCE | E43: =$E$42-$E$41 -> 0
D45: PREPARED BY: | E45: kenneth nuamah | F45: DATE: | G45: 45981
D48: REVIEWED BY: | F48: DATE:

Sheet AFRIEXIM USD
A1: Field_1 | B1: Field_2 | C1: Field_3 | D1: Field_4 | E1: Field_5 | F1: Field_6 | G1: Field_7 | H1: Field_8 | I1: FIELD_9
B4: DEPT | D4: OPERATIONS | E4: BANK ACCOUNT NUMBER | F4: 300058801200001
B6: BRANCH | D6: HEAD OFFICE | E6: GENERAL LEDGER NAME | F6: AFRIEXIM USD
B8: REPORTING DATE | D8: 20-Nov-25 | E8: GENERAL LEDGER NUMBER
B10: REPORTING UNIT | D10: RECONCILIATION
C13: 20-Nov-25 | D13: BALANCE PER BANK STATEMENT | E13: 4692166.9 | I13: CR
B15: SN | C15: DATE | D15: DESCRIPTION | E15: AMOUNT | F15: GL Ref No. | G15: AGING(DAYS) | H15: RECON
D17: ADD: DEBIT IN OUR BOOKS BUT NOT CREDITED BY AFRIEXIM
B18: 1 | C18: 19-Nov-2025 | D18: FX PURCHASE - USD/GHS @ 11.0150 | E18: 100000 | F18: FX PURCHASE - USD/GHS @ 11.0150 | G18: 1 | H18: INT DR
B19: 2 | C19: 20-Nov-2025 | D19: FX PURCHASE - USD/GHS @ 11.00 | E19: 40000 | F19: 2532401436634000 | G19: 0 | H19: INT DR
B20: 3 | C20: 20-Nov-2025 | D20: FX PURCHASE - USD/GHS @ 11.12 - UNERGROUND MINING ALLIANCE | E20: 3000000 | F20: 000UMAG253240001 | G20: 0 | H20: INT DR
D22: TOTAL: | E22: =SUM($E$18:$E$21) -> 3140000
D25: ADD: DEBIT ORIGINATED BY AFRIEXIM BUT NOT CREDITED IN OUR BOOKS
D28: TOTAL: | E28: =SUM($E$26:$E$27) -> 0
D31: LESS: CREDIT ORIGINATED BY AFRIEXIM BUT NOT DEBITED IN OUR BOOKS
B32: 1 | C32: 12-Nov-2025 | D32: N MSC BEN:EG5290040001 //ORD:8700206114 SWIFT REF:2025111200385413. PO:000 | E32: 700000 | F32: N MSC BEN:EG5290040001 //ORD:8700206114 SWIFT REF:2025111200385413. PO:000 | G32: 8 | H32: EXT CR
B33: 2 | C33: 18-Nov-2025 | D33: 599360 BEN:3000588012 ORD SEG627921/19-11-2025/2 | E33: 3000000 | F33: 599360 BEN:3000588012 ORD SEG627921/19-11-2025/2 | G33: 2 | H33: EXT CR
B34: 3 | C34: 19-Nov-2025 | D34: 599360 BEN:3000588012 ORD SEG628241/19-11-2025/2 | E34: 40000 | F34: 599360 BEN:3000588012 ORD SEG628241/19-11-2025/2 | G34: 1 | H34: EXT CR
B35: 4 | C35: 19-Nov-2025 | D35: 599360 ORD:. Nm:Fast BEN SEG627829/19-11-2025/2 | E35: 100000 | F35: 599360 ORD:. Nm:Fast BEN SEG627829/19-11-2025/2 | G35: 1 | H35: EXT CR
B36: 5 | C36: 19-Nov-2025 | D36: 599982 BEN:3000588012 ORD SEG629677/20-11-2025/2 | E36: 300000 | F36: ORD | G36: 1 | H36: EXT CR
D38: TOTAL: | E38: =SUM($E$32:$E$37) -> 4140000
D41: LESS: CREDIT IN OUR BOOKS BUT NOT DEBITED BY AFRIEXIM
D44: TOTAL: | E44: =SUM($E$42:$E$43) -> 0
D47: GRAND TOTAL | E47: =ABS(E13+$E$22-$E$44+$E$28-$E$38) -> 3692166.9
D48: INTERNAL ACCOUNT BALANCE AS AT Nov 20, 2025 | E48: 3692166.9 | I48: DR
D49: DIFFERENCE | E49: =$E$48-$E$47 -> 0
D51: PREPARED BY: | E51: kenneth nuamah | F51: DATE: | G51: 45981
D54: REVIEWED BY: | F54: DATE:

Sheet AFRIEXIM USD PAPSS
A1: Field_1 | B1: Field_2 | C1: Field_3 | D1: Field_4 | E1: Field_5 | F1: Field_6 | G1: Field_7 | H1: Field_8 | I1: FIELD_9
B4: DEPT | D4: OPERATIONS | E4: BANK ACCOUNT NUMBER | F4: EG179004000100300058801803001
B6: BRANCH | D6: HEAD OFFICE | E6: GENERAL LEDGER NAME | F6: AFRICAN EXIM BANK USD - PAPSS
B8: REPORTING DATE | D8: 20-Nov-25 | E8: GENERAL LEDGER NUMBER | F8: 0020000097020
B10: REPORTING UNIT | D10: RECONCILIATION
C13: 20-Nov-25 | D13: BALANCE PER BANK STATEMENT | E13: 578.25 | I13: CR
B15: SN | C15: DATE | D15: DESCRIPTION | E15: AMOUNT | F15: GL Ref No. | G15: AGING(DAYS) | H15: RECON
D17: ADD: DEBIT IN OUR BOOKS BUT NOT CREDITED BY AFRIEXIM
D20: TOTAL: | E20: =SUM($E$18:$E$19) -> 0
D23: ADD: DEBIT ORIGINATED BY AFRIEXIM BUT NOT CREDITED IN OUR BOOKS
D26: TOTAL: | E26: =SUM($E$24:$E$25) -> 0
D29: LESS: CREDIT ORIGINATED BY AFRIEXIM BUT NOT DEBITED IN OUR BOOKS
B30: 1 | C30: 07-Nov-2025 | D30: N MSC //PAPPS PAPSS USD SETTLEMENT | E30: 68.49 | F30: N MSC //PAPPS PAPSS USD SETTLEMENT | G30: 13 | H30: EXT CR
D32: TOTAL: | E32: =SUM($E$30:$E$31) -> 68.49
D35: LESS: CREDIT IN OUR BOOKS BUT NOT DEBITED BY AFRIEXIM
D38: TOTAL: | E38: =SUM($E$36:$E$37) -> 0
D41: GRAND TOTAL | E41: =ABS(E13+$E$20-$E$38+$E$26-$E$32) -> 509.76
D42: INTERNAL ACCOUNT BALANCE AS AT Nov 20, 2025 | E42: 509.76 | I42: CR
D43: DIFFERENCE | E43: =$E$42-$E$41 -> 0
D45: PREPARED BY: | E45: kenneth nuamah | F45: DATE: | G45: 45981
D48: REVIEWED BY: | F48: DATE:

Sheet AKTIF EUR
A1: Field_1 | B1: Field_2 | C1: Field_3 | D1: Field_4 | E1: Field_5 | F1: Field_6 | G1: Field_7 | H1: Field_8 | I1: FIELD_9
B4: DEPT | D4: OPERATIONS | E4: BANK ACCOUNT NUMBER | F4: ^TR540014300000000007408441
B6: BRANCH | D6: HEAD OFFICE | E6: GENERAL LEDGER NAME | F6: AKTIF EUR
B8: REPORTING DATE | D8: 20-Nov-25 | E8: GENERAL LEDGER NUMBER | F8: 0020000139018
B10: REPORTING UNIT | D10: RECONCILIATION
C13: 20-Nov-25 | D13: BALANCE PER BANK STATEMENT | E13: 0.82 | I13: CR
B15: SN | C15: DATE | D15: DESCRIPTION | E15: AMOUNT | F15: GL Ref No. | G15: AGING(DAYS) | H15: RECON
D17: ADD: DEBIT IN OUR BOOKS BUT NOT CREDITED BY AKTIF
D20: TOTAL: | E20: =SUM($E$18:$E$19) -> 0
D23: ADD: DEBIT ORIGINATED BY AKTIF BUT NOT CREDITED IN OUR BOOKS
D26: TOTAL: | E26: =SUM($E$24:$E$25) -> 0
D29: LESS: CREDIT ORIGINATED BY AKTIF BUT NOT DEBITED IN OUR BOOKS
D32: TOTAL: | E32: =SUM($E$30:$E$31) -> 0
D35: LESS: CREDIT IN OUR BOOKS BUT NOT DEBITED BY AKTIF
D38: TOTAL: | E38: =SUM($E$36:$E$37) -> 0
D41: GRAND TOTAL | E41: =ABS(E13+$E$20-$E$38+$E$26-$E$32) -> 0.82
D42: INTERNAL ACCOUNT BALANCE AS AT Nov 20, 2025 | E42: 0.82 | I42: CR
D43: DIFFERENCE | E43: =$E$42-$E$41 -> 0
D45: PREPARED BY: | E45: kenneth nuamah | F45: DATE: | G45: 45981
D48: REVIEWED BY: | F48: DATE:

Sheet AKTIF GBP
A1: Field_1 | B1: Field_2 | C1: Field_3 | D1: Field_4 | E1: Field_5 | F1: Field_6 | G1: Field_7 | H1: Field_8 | I1: FIELD_9
B4: DEPT | D4: OPERATIONS | E4: BANK ACCOUNT NUMBER | F4: ^TR430014300000000007408445
B6: BRANCH | D6: HEAD OFFICE | E6: GENERAL LEDGER NAME | F6: AKTIF GBP
B8: REPORTING DATE | D8: 20-Nov-25 | E8: GENERAL LEDGER NUMBER | F8: 0040000139012
B10: REPORTING UNIT | D10: RECONCILIATION
C13: 20-Nov-25 | D13: BALANCE PER BANK STATEMENT | E13: 51970 | I13: CR
B15: SN | C15: DATE | D15: DESCRIPTION | E15: AMOUNT | F15: GL Ref No. | G15: AGING(DAYS) | H15: RECON
D17: ADD: DEBIT IN OUR BOOKS BUT NOT CREDITED BY AKTIF
D20: TOTAL: | E20: =SUM($E$18:$E$19) -> 0
D23: ADD: DEBIT ORIGINATED BY AKTIF BUT NOT CREDITED IN OUR BOOKS
D26: TOTAL: | E26: =SUM($E$24:$E$25) -> 0
D29: LESS: CREDIT ORIGINATED BY AKTIF BUT NOT DEBITED IN OUR BOOKS
D32: TOTAL: | E32: =SUM($E$30:$E$31) -> 0
D35: LESS: CREDIT IN OUR BOOKS BUT NOT DEBITED BY AKTIF
D38: TOTAL: | E38: =SUM($E$36:$E$37) -> 0
D41: GRAND TOTAL | E41: =ABS(E13+$E$20-$E$38+$E$26-$E$32) -> 51970
D42: INTERNAL ACCOUNT BALANCE AS AT Nov 20, 2025 | E42: 51970 | I42: CR
D43: DIFFERENCE | E43: =$E$42-$E$41 -> 0
D45: PREPARED BY: | E45: kenneth nuamah | F45: DATE: | G45: 45981
D48: REVIEWED BY: | F48: DATE:

Sheet AKTIF USD
A1: Field_1 | B1: Field_2 | C1: Field_3 | D1: Field_4 | E1: Field_5 | F1: Field_6 | G1: Field_7 | H1: Field_8 | I1: FIELD_9
B4: DEPT | D4: OPERATIONS | E4: BANK ACCOUNT NUMBER | F4: ^TR540014300000000007408441
B6: BRANCH | D6: HEAD OFFICE | E6: GENERAL LEDGER NAME | F6: AKTIF USD
B8: REPORTING DATE | D8: 20-Nov-25 | E8: GENERAL LEDGER NUMBER | F8: 0020000139018
B10: REPORTING UNIT | D10: RECONCILIATION
C13: 20-Nov-25 | D13: BALANCE PER BANK STATEMENT | E13: 336633.39 | I13: CR
B15: SN | C15: DATE | D15: DESCRIPTION | E15: AMOUNT | F15: GL Ref No. | G15: AGING(DAYS) | H15: RECON
D17: ADD: DEBIT IN OUR BOOKS BUT NOT CREDITED BY AKTIF
D20: TOTAL: | E20: =SUM($E$18:$E$19) -> 0
D23: ADD: DEBIT ORIGINATED BY AKTIF BUT NOT CREDITED IN OUR BOOKS
D26: TOTAL: | E26: =SUM($E$24:$E$25) -> 0
D29: LESS: CREDIT ORIGINATED BY AKTIF BUT NOT DEBITED IN OUR BOOKS
D32: TOTAL: | E32: =SUM($E$30:$E$31) -> 0
D35: LESS: CREDIT IN OUR BOOKS BUT NOT DEBITED BY AKTIF
D38: TOTAL: | E38: =SUM($E$36:$E$37) -> 0
D41: GRAND TOTAL | E41: =ABS(E13+$E$20-$E$38+$E$26-$E$32) -> 336633.39
D42: INTERNAL ACCOUNT BALANCE AS AT Nov 20, 2025 | E42: 336633.39 | I42: CR
D43: DIFFERENCE | E43: =$E$42-$E$41 -> 0
D45: PREPARED BY: | E45: kenneth nuamah | F45: DATE: | G45: 45981
D48: REVIEWED BY: | F48: DATE:

Sheet ARAB TURKISH EUR
A1: Field_1 | B1: Field_2 | C1: Field_3 | D1: Field_4 | E1: Field_5 | F1: Field_6 | G1: Field_7 | H1: Field_8 | I1: FIELD_9
B4: DEPT | D4: OPERATIONS | E4: BANK ACCOUNT NUMBER | F4: 32000019867
B6: BRANCH | D6: HEAD OFFICE | E6: GENERAL LEDGER NAME | F6: ARAB TURKISH BANK - EUR
B8: REPORTING DATE | D8: 20-Nov-25 | E8: GENERAL LEDGER NUMBER | F8: 0030000089019
B10: REPORTING UNIT | D10: RECONCILIATION
C13: 20-Nov-25 | D13: BALANCE PER BANK STATEMENT | E13: 2158890.1 | I13: CR
B15: SN | C15: DATE | D15: DESCRIPTION | E15: AMOUNT | F15: GL Ref No. | G15: AGING(DAYS) | H15: RECON
D17: ADD: DEBIT IN OUR BOOKS BUT NOT CREDITED BY ARAB TURKISH BANK
D20: TOTAL: | E20: =SUM($E$18:$E$19) -> 0
D23: ADD: DEBIT ORIGINATED BY ARAB TURKISH BANK BUT NOT CREDITED IN OUR BOOKS
D26: TOTAL: | E26: =SUM($E$24:$E$25) -> 0
D29: LESS: CREDIT ORIGINATED BY ARAB TURKISH BANK BUT NOT DEBITED IN OUR BOOKS
B30: 1 | C30: 19-Nov-2025 | D30: 20251119-248 FT2532300293 FT2532300293 | E30: 48.05 | F30: 20251119-248 FT2532300293 FT2532300293 | G30: 1 | H30: EXT CR
B31: 2 | C31: 20-Nov-2025 | D31: 20251120-249 FT2532400307 TRANSFER | E31: 1.47 | F31: TRANSFER | G31: 0 | H31: EXT CR
D33: TOTAL: | E33: =SUM($E$30:$E$32) -> 49.52
D36: LESS: CREDIT IN OUR BOOKS BUT NOT DEBITED BY ARAB TURKISH BANK
D39: TOTAL: | E39: =SUM($E$37:$E$38) -> 0
D42: GRAND TOTAL | E42: =ABS(E13+$E$20-$E$39+$E$26-$E$33) -> 2158840.6
D43: INTERNAL ACCOUNT BALANCE AS AT Nov 20, 2025 | E43: 2158840.6 | I43: DR
D44: DIFFERENCE | E44: =$E$43-$E$42 -> 0
D46: PREPARED BY: | E46: kenneth nuamah | F46: DATE: | G46: 45981
D49: REVIEWED BY: | F49: DATE:

Sheet ARAB TURKISH USD
A1: Field_1 | B1: Field_2 | C1: Field_3 | D1: Field_4 | E1: Field_5 | F1: Field_6 | G1: Field_7 | H1: Field_8 | I1: FIELD_9
B4: DEPT | D4: OPERATIONS | E4: BANK ACCOUNT NUMBER | F4: 32000029245
B6: BRANCH | D6: HEAD OFFICE | E6: GENERAL LEDGER NAME | F6: ARAB TURKISH BANK - USD
B8: REPORTING DATE | D8: 20-Nov-25 | E8: GENERAL LEDGER NUMBER | F8: 0020000089011
B10: REPORTING UNIT | D10: RECONCILIATION
C13: 20-Nov-25 | D13: BALANCE PER BANK STATEMENT | E13: 77332.97 | I13: CR
B15: SN | C15: DATE | D15: DESCRIPTION | E15: AMOUNT | F15: GL Ref No. | G15: AGING(DAYS) | H15: RECON
D17: ADD: DEBIT IN OUR BOOKS BUT NOT CREDITED BY ARAB TURKISH BANK
D20: TOTAL: | E20: =SUM($E$18:$E$19) -> 0
D23: ADD: DEBIT ORIGINATED BY ARAB TURKISH BANK BUT NOT CREDITED IN OUR BOOKS
D26: TOTAL: | E26: =SUM($E$24:$E$25) -> 0
D29: LESS: CREDIT ORIGINATED BY ARAB TURKISH BANK BUT NOT DEBITED IN OUR BOOKS
D32: TOTAL: | E32: =SUM($E$30:$E$31) -> 0
D35: LESS: CREDIT IN OUR BOOKS BUT NOT DEBITED BY ARAB TURKISH BANK
D38: TOTAL: | E38: =SUM($E$36:$E$37) -> 0
D41: GRAND TOTAL | E41: =ABS(E13+$E$20-$E$38+$E$26-$E$32) -> 77332.97
D42: INTERNAL ACCOUNT BALANCE AS AT Nov 20, 2025 | E42: 77332.97 | I42: CR
D43: DIFFERENCE | E43: =$E$42-$E$41 -> 0
D45: PREPARED BY: | E45: kenneth nuamah | F45: DATE: | G45: 45981
D48: REVIEWED BY: | F48: DATE:

Sheet BANK OF BEIRUT EUR
A1: Field_1 | B1: Field_2 | C1: Field_3 | D1: Field_4 | E1: Field_5 | F1: Field_6 | G1: Field_7 | H1: Field_8 | I1: FIELD_9
B4: DEPT | D4: OPERATIONS | E4: BANK ACCOUNT NUMBER | F4: ^4016093345900
B6: BRANCH | D6: HEAD OFFICE | E6: GENERAL LEDGER NAME | F6: BANK OF BEIRUT EUR
B8: REPORTING DATE | D8: 20-Nov-25 | E8: GENERAL LEDGER NUMBER | F8: 0030000099012
B10: REPORTING UNIT | D10: RECONCILIATION
C13: 20-Nov-25 | D13: BALANCE PER BANK STATEMENT | E13: 0 | I13: DR
B15: SN | C15: DATE | D15: DESCRIPTION | E15: AMOUNT | F15: GL Ref No. | G15: AGING(DAYS) | H15: RECON
D17: ADD: DEBIT IN OUR BOOKS BUT NOT CREDITED BY BEIRUT
D20: TOTAL: | E20: =SUM($E$18:$E$19) -> 0
D23: ADD: DEBIT ORIGINATED BY BEIRUT BUT NOT CREDITED IN OUR BOOKS
D26: TOTAL: | E26: =SUM($E$24:$E$25) -> 0
D29: LESS: CREDIT ORIGINATED BY BEIRUT BUT NOT DEBITED IN OUR BOOKS
D32: TOTAL: | E32: =SUM($E$30:$E$31) -> 0
D35: LESS: CREDIT IN OUR BOOKS BUT NOT DEBITED BY BEIRUT
D38: TOTAL: | E38: =SUM($E$36:$E$37) -> 0
D41: GRAND TOTAL | E41: =ABS(E13+$E$20-$E$38+$E$26-$E$32) -> 0
D42: INTERNAL ACCOUNT BALANCE AS AT Nov 20, 2025 | E42: 0 | I42: DR
D43: DIFFERENCE | E43: =$E$42-$E$41 -> 0
D45: PREPARED BY: | E45: kenneth nuamah | F45: DATE: | G45: 45981
D48: REVIEWED BY: | F48: DATE:

Sheet BANK OF BEIRUT GBP
A1: Field_1 | B1: Field_2 | C1: Field_3 | D1: Field_4 | E1: Field_5 | F1: Field_6 | G1: Field_7 | H1: Field_8 | I1: FIELD_9
B4: DEPT | D4: OPERATIONS | E4: BANK ACCOUNT NUMBER | F4: ^0116093345900
B6: BRANCH | D6: HEAD OFFICE | E6: GENERAL LEDGER NAME | F6: BANK OF BEIRUT GBP
B8: REPORTING DATE | D8: 20-Nov-25 | E8: GENERAL LEDGER NUMBER | F8: 0040000099018
B10: REPORTING UNIT | D10: RECONCILIATION
C13: 20-Nov-25 | D13: BALANCE PER BANK STATEMENT | E13: 0 | I13: DR
B15: SN | C15: DATE | D15: DESCRIPTION | E15: AMOUNT | F15: GL Ref No. | G15: AGING(DAYS) | H15: RECON
D17: ADD: DEBIT IN OUR BOOKS BUT NOT CREDITED BY BEIRUT
D20: TOTAL: | E20: =SUM($E$18:$E$19) -> 0
D23: ADD: DEBIT ORIGINATED BY BEIRUT BUT NOT CREDITED IN OUR BOOKS
D26: TOTAL: | E26: =SUM($E$24:$E$25) -> 0
D29: LESS: CREDIT ORIGINATED BY BEIRUT BUT NOT DEBITED IN OUR BOOKS
D32: TOTAL: | E32: =SUM($E$30:$E$31) -> 0
D35: LESS: CREDIT IN OUR BOOKS BUT NOT DEBITED BY BEIRUT
D38: TOTAL: | E38: =SUM($E$36:$E$37) -> 0
D41: GRAND TOTAL | E41: =ABS(E13+$E$20-$E$38+$E$26-$E$32) -> 0
D42: INTERNAL ACCOUNT BALANCE AS AT Nov 20, 2025 | E42: 0 | I42: DR
D43: DIFFERENCE | E43: =$E$42-$E$41 -> 0
D45: PREPARED BY: | E45: kenneth nuamah | F45: DATE: | G45: 45981
D48: REVIEWED BY: | F48: DATE:

Sheet BANK OF BEIRUT USD
A1: Field_1 | B1: Field_2 | C1: Field_3 | D1: Field_4 | E1: Field_5 | F1: Field_6 | G1: Field_7 | H1: Field_8 | I1: FIELD_9
B4: DEPT | D4: OPERATIONS | E4: BANK ACCOUNT NUMBER | F4: ^1116093345900
B6: BRANCH | D6: HEAD OFFICE | E6: GENERAL LEDGER NAME | F6: BANK OF BEIRUT USD
B8: REPORTING DATE | D8: 20-Nov-25 | E8: GENERAL LEDGER NUMBER | F8: 0020000099015
B10: REPORTING UNIT | D10: RECONCILIATION
C13: 20-Nov-25 | D13: BALANCE PER BANK STATEMENT | E13: 4668031.8 | I13: CR
B15: SN | C15: DATE | D15: DESCRIPTION | E15: AMOUNT | F15: GL Ref No. | G15: AGING(DAYS) | H15: RECON
D17: ADD: DEBIT IN OUR BOOKS BUT NOT CREDITED BY BEIRUT
D20: TOTAL: | E20: =SUM($E$18:$E$19) -> 0
D23: ADD: DEBIT ORIGINATED BY BEIRUT BUT NOT CREDITED IN OUR BOOKS
D26: TOTAL: | E26: =SUM($E$24:$E$25) -> 0
D29: LESS: CREDIT ORIGINATED BY BEIRUT BUT NOT DEBITED IN OUR BOOKS
D32: TOTAL: | E32: =SUM($E$30:$E$31) -> 0
D35: LESS: CREDIT IN OUR BOOKS BUT NOT DEBITED BY BEIRUT
D38: TOTAL: | E38: =SUM($E$36:$E$37) -> 0
D41: GRAND TOTAL | E41: =ABS(E13+$E$20-$E$38+$E$26-$E$32) -> 4668031.8
D42: INTERNAL ACCOUNT BALANCE AS AT Nov 20, 2025 | E42: 4668031.8 | I42: CR
D43: DIFFERENCE | E43: =$E$42-$E$41 -> 0
D45: PREPARED BY: | E45: kenneth nuamah | F45: DATE: | G45: 45981
D48: REVIEWED BY: | F48: DATE:

Sheet COTE DVOIRE XOF
A1: Field_1 | B1: Field_2 | C1: Field_3 | D1: Field_4 | E1: Field_5 | F1: Field_6 | G1: Field_7 | H1: Field_8 | I1: FIELD_9
B4: DEPT | D4: OPERATIONS | E4: BANK ACCOUNT NUMBER | F4: 99951400001
B6: BRANCH | D6: HEAD OFFICE | E6: GENERAL LEDGER NAME | F6: BSIC COTE D'IVOIRE - XOF
B8: REPORTING DATE | D8: 20-Nov-25 | E8: GENERAL LEDGER NUMBER | F8: 0050154485011
B10: REPORTING UNIT | D10: RECONCILIATION
C13: 20-Nov-25 | D13: BALANCE PER BANK STATEMENT | E13: 6570525 | I13: CR
B15: SN | C15: DATE | D15: DESCRIPTION | E15: AMOUNT | F15: GL Ref No. | G15: AGING(DAYS) | H15: RECON
D17: ADD: DEBIT IN OUR BOOKS BUT NOT CREDITED BY COTE D'IVOIRE
D20: TOTAL: | E20: =SUM($E$18:$E$19) -> 0
D23: ADD: DEBIT ORIGINATED BY COTE D'IVOIRE BUT NOT CREDITED IN OUR BOOKS
D26: TOTAL: | E26: =SUM($E$24:$E$25) -> 0
D29: LESS: CREDIT ORIGINATED BY COTE D'IVOIRE BUT NOT DEBITED IN OUR BOOKS
D32: TOTAL: | E32: =SUM($E$30:$E$31) -> 0
D35: LESS: CREDIT IN OUR BOOKS BUT NOT DEBITED BY COTE D'IVOIRE
D38: TOTAL: | E38: =SUM($E$36:$E$37) -> 0
D41: GRAND TOTAL | E41: =ABS(E13+$E$20-$E$38+$E$26-$E$32) -> 6570525
D42: INTERNAL ACCOUNT BALANCE AS AT Nov 20, 2025 | E42: 6570525 | I42: CR
D43: DIFFERENCE | E43: =$E$42-$E$41 -> 0
D45: PREPARED BY: | E45: kenneth nuamah | F45: DATE: | G45: 45981
D48: REVIEWED BY: | F48: DATE:

Sheet ECOBANK
A1: Field_1 | B1: Field_2 | C1: Field_3 | D1: Field_4 | E1: Field_5 | F1: Field_6 | G1: Field_7 | H1: Field_8 | I1: FIELD_9
B4: DEPT | D4: OPERATIONS | E4: BANK ACCOUNT NUMBER | F4: 1441001256551
B6: BRANCH | D6: HEAD OFFICE | E6: GENERAL LEDGER NAME | F6: ECOBANK
B8: REPORTING DATE | D8: 20-Nov-25 | E8: GENERAL LEDGER NUMBER | F8: 0010000094014
B10: REPORTING UNIT | D10: RECONCILIATION
C13: 20-Nov-25 | D13: BALANCE PER BANK STATEMENT | E13: 2623086.9 | I13: CR
B15: SN | C15: DATE | D15: DESCRIPTION | E15: AMOUNT | F15: GL Ref No. | G15: AGING(DAYS) | H15: RECON
D17: ADD: DEBIT IN OUR BOOKS BUT NOT CREDITED BY ECOBANK
D20: TOTAL: | E20: =SUM($E$18:$E$19) -> 0
D23: ADD: DEBIT ORIGINATED BY ECOBANK BUT NOT CREDITED IN OUR BOOKS
D26: TOTAL: | E26: =SUM($E$24:$E$25) -> 0
D29: LESS: CREDIT ORIGINATED BY ECOBANK BUT NOT DEBITED IN OUR BOOKS
D32: TOTAL: | E32: =SUM($E$30:$E$31) -> 0
D35: LESS: CREDIT IN OUR BOOKS BUT NOT DEBITED BY ECOBANK
D38: TOTAL: | E38: =SUM($E$36:$E$37) -> 0
D41: GRAND TOTAL | E41: =ABS(E13+$E$20-$E$38+$E$26-$E$32) -> 2623086.9
D42: INTERNAL ACCOUNT BALANCE AS AT Nov 20, 2025 | E42: 2623086.9 | I42: CR
D43: DIFFERENCE | E43: =$E$42-$E$41 -> 0
D45: PREPARED BY: | E45: kenneth nuamah | F45: DATE: | G45: 45981
D48: REVIEWED BY: | F48: DATE:

Sheet GCB
A1: Field_1 | B1: Field_2 | C1: Field_3 | D1: Field_4 | E1: Field_5 | F1: Field_6 | G1: Field_7 | H1: Field_8 | I1: FIELD_9
B4: DEPT | D4: OPERATIONS | E4: BANK ACCOUNT NUMBER | F4: ^1331130004604
B6: BRANCH | D6: HEAD OFFICE | E6: GENERAL LEDGER NAME | F6: GCB
B8: REPORTING DATE | D8: 20-Nov-25 | E8: GENERAL LEDGER NUMBER | F8: 0010000095017
B10: REPORTING UNIT | D10: RECONCILIATION
C13: 20-Nov-25 | D13: BALANCE PER BANK STATEMENT | E13: 11414017 | I13: CR
B15: SN | C15: DATE | D15: DESCRIPTION | E15: AMOUNT | F15: GL Ref No. | G15: AGING(DAYS) | H15: RECON
D17: ADD: DEBIT IN OUR BOOKS BUT NOT CREDITED BY GCB
D20: TOTAL: | E20: =SUM($E$18:$E$19) -> 0
D23: ADD: DEBIT ORIGINATED BY GCB BUT NOT CREDITED IN OUR BOOKS
D26: TOTAL: | E26: =SUM($E$24:$E$25) -> 0
D29: LESS: CREDIT ORIGINATED BY GCB BUT NOT DEBITED IN OUR BOOKS
B30: 1 | C30: 16-Sep-2025 | D30: ZENITH BANK GH CHQ - UIC JESUS KIDS DAY CARE CENTRE~002363 - DEP NTRE~002363 - DEP. AT CAPECOAST AT CAPECOAST | E30: 5359.25 | G30: 65 | H30: EXT CR
B31: 2 | C31: 02-Oct-2025 | D31: ZENITH BANK GH CHQ - MIKONVILL INFANTS SCHOOL~000922 - DEP. AT C 00922 - DEP. AT CAPECOAST PECOAST | E31: 9775 | G31: 49 | H31: EXT CR
B32: 3 | C32: 13-Oct-2025 | D32: AGRICULTURAL DEVELOPMENT CHQ - CALVARY HILLCREST SCHOOLS BOOKS ACCOUNT~000096 - DEP. AT CAPECOAST | E32: 5525 | G32: 38 | H32: EXT CR
D34: TOTAL: | E34: =SUM($E$30:$E$33) -> 20659.25
D37: LESS: CREDIT IN OUR BOOKS BUT NOT DEBITED BY GCB
D40: TOTAL: | E40: =SUM($E$38:$E$39) -> 0
D43: GRAND TOTAL | E43: =ABS(E13+$E$20-$E$40+$E$26-$E$34) -> 11393357
D44: INTERNAL ACCOUNT BALANCE AS AT Nov 20, 2025 | E44: 11393357 | I44: DR
D45: DIFFERENCE | E45: =$E$44-$E$43 -> 0
D47: PREPARED BY: | E47: kenneth nuamah | F47: DATE: | G47: 45981
D50: REVIEWED BY: | F50: DATE:

Sheet GCB 2 & 3
A1: Field_1 | B1: Field_2 | C1: Field_3 | D1: Field_4 | E1: Field_5 | F1: Field_6 | G1: Field_7 | H1: Field_8 | I1: FIELD_9
B4: DEPT | D4: OPERATIONS | E4: BANK ACCOUNT NUMBER | F4: '1151130006048
B6: BRANCH | D6: HEAD OFFICE | E6: GENERAL LEDGER NAME | F6: GCB BANK LTD 3
B8: REPORTING DATE | D8: 20-Nov-25 | E8: GENERAL LEDGER NUMBER
B10: REPORTING UNIT | D10: RECONCILIATION
C13: 20-Nov-25 | D13: BALANCE PER BANK STATEMENT | E13: 411946.93 | I13: CR
B15: SN | C15: DATE | D15: DESCRIPTION | E15: AMOUNT | F15: GL Ref No. | G15: AGING(DAYS) | H15: RECON
D17: ADD: DEBIT IN OUR BOOKS BUT NOT CREDITED BY GCB
D20: TOTAL: | E20: =SUM($E$18:$E$19) -> 0
D23: ADD: DEBIT ORIGINATED BY GCB BUT NOT CREDITED IN OUR BOOKS
D26: TOTAL: | E26: =SUM($E$24:$E$25) -> 0
D29: LESS: CREDIT ORIGINATED BY GCB BUT NOT DEBITED IN OUR BOOKS
D32: TOTAL: | E32: =SUM($E$30:$E$31) -> 0
D35: LESS: CREDIT IN OUR BOOKS BUT NOT DEBITED BY GCB
D38: TOTAL: | E38: =SUM($E$36:$E$37) -> 0
D41: GRAND TOTAL | E41: =ABS(E13+$E$20-$E$38+$E$26-$E$32) -> 411946.93
D42: INTERNAL ACCOUNT BALANCE AS AT Nov 20, 2025 | E42: 411946.93 | I42: CR
D43: DIFFERENCE | E43: =$E$42-$E$41 -> 0
D45: PREPARED BY: | E45: kenneth nuamah | F45: DATE: | G45: 45981
D48: REVIEWED BY: | F48: DATE:

Sheet GHIB EUR
A1: Field_1 | B1: Field_2 | C1: Field_3 | D1: Field_4 | E1: Field_5 | F1: Field_6 | G1: Field_7 | H1: Field_8 | I1: FIELD_9
B4: DEPT | D4: OPERATIONS | E4: BANK ACCOUNT NUMBER | F4: ^51162603
B6: BRANCH | D6: HEAD OFFICE | E6: GENERAL LEDGER NAME | F6: GHIB - EUR
B8: REPORTING DATE | D8: 20-Nov-25 | E8: GENERAL LEDGER NUMBER | F8: 0030000032011
B10: REPORTING UNIT | D10: RECONCILIATION
C13: 20-Nov-25 | D13: BALANCE PER BANK STATEMENT | E13: 1369750.5 | I13: CR
B15: SN | C15: DATE | D15: DESCRIPTION | E15: AMOUNT | F15: GL Ref No. | G15: AGING(DAYS) | H15: RECON
D17: ADD: DEBIT IN OUR BOOKS BUT NOT CREDITED BY GHIB
B18: 1 | C18: 20-Nov-2025 | D18: FX PURCHASE EUR, XOF @ 669.07614038462 000FXSP253240501 | E18: 520000 | F18: 000FXSP253240501 | G18: 0 | H18: INT DR
D20: TOTAL: | E20: =SUM($E$18:$E$19) -> 520000
D23: ADD: DEBIT ORIGINATED BY GHIB BUT NOT CREDITED IN OUR BOOKS
B24: 1 | C24: 12-Nov-2025 | D24: N TRF OMNOPA20251053 //FT2531600471 Outward Telex Payment | E24: 39060 | F24: OMNOPA20251053 | G24: 8 | H24: EXT DR
B25: 2 | C25: 13-Nov-2025 | D25: 20251113-204 FT2531756740 OMNTR20251789 | E25: 38.5 | F25: OMNTR20251789 | G25: 7 | H25: EXT DR
B26: 3 | C26: 14-Nov-2025 | D26: 20251114-205 FT2531896640 OMNAP20254337 | E26: 38.5 | F26: OMNAP20254337 | G26: 6 | H26: EXT DR
B27: 4 | C27: 17-Nov-2025 | D27: 20251117-206 FT2532141252 OMNAP20254128R | E27: 38.5 | F27: OMNAP20254128R | G27: 3 | H27: EXT DR
B28: 5 | C28: 19-Nov-2025 | D28: 20251119-208 FT2532306347 OMNTR20251831 | E28: 38.5 | F28: OMNTR20251831 | G28: 1 | H28: EXT DR
B29: 6 | C29: 19-Nov-2025 | D29: 20251119-208 FT2532306347 OMNTR20251831 | E29: 504.25 | F29: OMNTR20251831 | G29: 1 | H29: EXT DR
B30: 7 | C30: 20-Nov-2025 | D30: 20251120-209 FT2532404194 OMNAP20254437 | E30: 22 | F30: OMNAP20254437 | G30: 0 | H30: EXT DR
B31: 8 | C31: 20-Nov-2025 | D31: 20251120-209 FT2532493040 OMNAP20254431 | E31: 38.5 | F31: OMNAP20254431 | G31: 0 | H31: EXT DR
B32: 9 | C32: 20-Nov-2025 | D32: 20251120-209 FT2532493040 OMNAP20254431 | E32: 4659 | F32: OMNAP20254431 | G32: 0 | H32: EXT DR
D34: TOTAL: | E34: =SUM($E$24:$E$33) -> 44437.75
D37: LESS: CREDIT ORIGINATED BY GHIB BUT NOT DEBITED IN OUR BOOKS
B38: 1 | C38: 05-Nov-2025 | D38: N TRF NONREF //FT2530979005 Outward Telex Payment | E38: 2221.64 | F38: N TRF NONREF //FT2530979005 Outward Telex Payment | G38: 15 | H38: EXT CR
D40: TOTAL: | E40: =SUM($E$38:$E$39) -> 2221.64
D43: LESS: CREDIT IN OUR BOOKS BUT NOT DEBITED BY GHIB
B44: 1 | C44: 20-Nov-2025 | D44: OMNTR20251870 TRF IFO EKOAGROS | E44: 250 | F44: OMNTR20251870 | G44: 0 | H44: INT CR
B45: 2 | C45: 20-Nov-2025 | D45: OMNTR20251873 TRF IFO STEPHANIE PEARL ADAMS | E45: 1000 | F45: OMNTR20251873 | G45: 0 | H45: INT CR
B46: 3 | C46: 20-Nov-2025 | D46: OMNTR20251866 TRF IFO T MARK CONSEILS | E46: 5510 | F46: OMNTR20251866 | G46: 0 | H46: INT CR
B47: 4 | C47: 20-Nov-2025 | D47: OMNAP20254482 TRF IFO KIKA LT UAB | E47: 11646 | F47: OMNAP20254482 | G47: 0 | H47: INT CR
B48: 5 | C48: 20-Nov-2025 | D48: OMNOPA20251081 TRF IFO T.C.M DI TORTORA GAETANO & C.S.R.L | E48: 41514.16 | F48: OMNOPA20251081 | G48: 0 | H48: INT CR
D50: TOTAL: | E50: =SUM($E$44:$E$49) -> 59920.16
D53: GRAND TOTAL | E53: =ABS(E13+$E$20-$E$50+$E$34-$E$40) -> 1872046.4
D54: INTERNAL ACCOUNT BALANCE AS AT Nov 20, 2025 | E54: 1872046.4 | I54: DR
D55: DIFFERENCE | E55: =$E$54-$E$53 -> 0
D57: PREPARED BY: | E57: kenneth nuamah | F57: DATE: | G57: 45981
D60: REVIEWED BY: | F60: DATE:

Sheet GHIB GBP
A1: Field_1 | B1: Field_2 | C1: Field_3 | D1: Field_4 | E1: Field_5 | F1: Field_6 | G1: Field_7 | H1: Field_8 | I1: FIELD_9
B4: DEPT | D4: OPERATIONS | E4: BANK ACCOUNT NUMBER | F4: ^51162601
B6: BRANCH | D6: HEAD OFFICE | E6: GENERAL LEDGER NAME | F6: GHIB - GBP
B8: REPORTING DATE | D8: 20-Nov-25 | E8: GENERAL LEDGER NUMBER | F8: 0040000032019
B10: REPORTING UNIT | D10: RECONCILIATION
C13: 20-Nov-25 | D13: BALANCE PER BANK STATEMENT | E13: 320144.76 | I13: CR
B15: SN | C15: DATE | D15: DESCRIPTION | E15: AMOUNT | F15: GL Ref No. | G15: AGING(DAYS) | H15: RECON
D17: ADD: DEBIT IN OUR BOOKS BUT NOT CREDITED BY GHIB
D20: TOTAL: | E20: =SUM($E$18:$E$19) -> 0
D23: ADD: DEBIT ORIGINATED BY GHIB BUT NOT CREDITED IN OUR BOOKS
